<?xml version="1.0"?><robot name="vehicle">


  <link name="base_link">
    <visual>
      <geometry>
        <box size="0.25 0.35 0.17"/>
      </geometry>
      <material name="blue">
        <color rgba="1 0 0 1"/>
      </material>
    </visual>
    <collision>
      <geometry>
        <box size="0.25 0.35 0.17"/>
      </geometry>
    </collision>
  </link>

  <link name="right_front_wheel">
    <visual>
      <origin rpy="1.57075 0.0 0.0" xyz="0.0 0.0 0.0"/>
      <geometry>
        <cylinder radius="0.04" length="0.05"/>
      </geometry>
      <material name="black">
        <color rgba="0.0 0.0 0.0 1.0"/>
      </material>
    </visual>
    <collision>
      <geometry>
        <cylinder radius="0.04" length="0.05"/>
      </geometry>
    </collision>
  </link>

  <joint name="right_front_wheel_to_base" type="continuous">
    <parent link="base_link"/>
    <child link="right_front_wheel"/>
    <axis xyz="0.0 1.0 0.0"/>
    <origin xyz="0.104 -0.21 -0.106"/>
  </joint>

  <link name="right_rear_wheel">
    <visual>
      <origin rpy="1.57075 0.0 0.0" xyz="0.0 0.0 0.0"/>
      <geometry>
        <cylinder radius="0.04" length="0.05"/>
      </geometry>
      <material name="black">
        <color rgba="0.0 0.0 0.0 1.0"/>
      </material>
    </visual>
    <collision>
      <geometry>
        <cylinder radius="0.04" length="0.05"/>
      </geometry>
    </collision>
  </link>

  <joint name="right_rear_wheel_to_base" type="continuous">
    <parent link="base_link"/>
    <child link="right_rear_wheel"/>
    <axis xyz="0.0 1.0 0.0"/>
    <origin xyz="-0.104 -0.21 -0.106"/>
  </joint>

    <link name="left_rear_wheel">
    <visual>
      <origin rpy="1.57075 0.0 0.0" xyz="0.0 0.0 0.0"/>
      <geometry>
        <cylinder radius="0.04" length="0.05"/>
      </geometry>
      <material name="black">
        <color rgba="0.0 0.0 0.0 1.0"/>
      </material>
    </visual>
    <collision>
      <geometry>
        <cylinder radius="0.04" length="0.05"/>
      </geometry>
    </collision>
  </link>

  <joint name="left_rear_wheel_to_base" type="continuous">
    <parent link="base_link"/>
    <child link="left_rear_wheel"/>
    <axis xyz="0.0 1.0 0.0"/>
    <origin xyz="-0.104 0.21 -0.106"/>
  </joint>

  <link name="left_front_wheel">
    <visual>
      <origin rpy="1.57075 0.0 0.0" xyz="0.0 0.0 0.0"/>
      <geometry>
        <cylinder radius="0.04" length="0.05"/>
      </geometry>
      <material name="black">
        <color rgba="0.0 0.0 0.0 1.0"/>
      </material>
    </visual>
    <collision>
      <geometry>
        <cylinder radius="0.04" length="0.05"/>
      </geometry>
    </collision>
  </link>

  <joint name="left_front_wheel_to_base" type="continuous">
    <parent link="base_link"/>
    <child link="left_front_wheel"/>
    <axis xyz="0.0 1.0 0.0"/>
    <origin xyz="0.104 0.21 -0.106"/>
  </joint>
  

  

</robot>